Workbook
Name Slicer_Clean_Enrollment_Date: #N/A
Name Slicer_Enrollment_Date: #N/A
Name Slicer_Enrollment_Date1: #N/A
Name Slicer_Enrollment_Status: #N/A
Name Slicer_Enrollment_Status2: #N/A
Name Slicer_Gender: #N/A
Name Slicer_Gender2: #N/A
Name Slicer_Program2: #N/A
Name Slicer_Program4: #N/A
Name Slicer_Study_Mode1: #N/A
Name Slicer_Study_Mode2: #N/A

Sheet Project_Index
A1: No. | B1: Student Name | C1: Project Title | D1: Dataset Sheet | E1: Rows | F1: Columns | G1: Status | I1: Data Quality Note
A2: 1 | B2: Aba Muxudiin Ahmed | C2: Student Enrollment Data Analysis Using Excel | D2: 01_Enrollment | E2: 300 | F2: 7 | G2: Ready | I2: Each project dataset now includes 15 additional empty cells in every one of its 7 columns for missing-value cleaning practice.
A3: 2 | B3: Abdikarim Ismail Ali | C3: Customer Purchase & Sales Performance Analysis Using Excel | D3: 02_Sales | E3: 300 | F3: 7 | G3: Ready
A4: 3 | B4: Abdinajib Abdullahi Muse | C4: Employee Attendance Data Analysis Using Excel | D4: 03_Emp_Attendance | E4: 300 | F4: 7 | G4: Ready
A5: 4 | B5: Aisha Mohamed Abdullahi | C5: Restaurant Sales and Customer Analysis Using Excel | D5: 04_Restaurant | E5: 300 | F5: 7 | G5: Ready
A6: 5 | B6: Aniso Ahmed Mohamud | C6: TITLE NOT PROVIDED | E6: 0 | F6: 0 | G6: Project title needed
A7: 6 | B7: Axmed Abduqadir Iman | C7: Electricity Consumption Data Analysis Using Excel | D7: 06_Electricity | E7: 300 | F7: 7 | G7: Ready
A8: 7 | B8: Ayuub Abdullahi Isxaakh | C8: Hospital Patient Data Analysis Using Excel | D8: 07_Hospital | E8: 300 | F8: 7 | G8: Ready
A9: 8 | B9: Cayni Abuukar Maxamuud | C9: Real Estate Property Data Analysis Using Excel | D9: 08_Real_Estate | E9: 300 | F9: 7 | G9: Ready
A10: 9 | B10: Deqo Abdulkhadir Hussein | C10: Student Attendance and Academic Analysis | D10: 09_Academic | E10: 300 | F10: 7 | G10: Ready
A11: 10 | B11: Faadumo Mahamed Yusuf | C11: Internet Usage Data Analysis | D11: 10_Internet | E11: 300 | F11: 7 | G11: Ready
A12: 11 | B12: Fardowso Gamadiid Imaan | C12: Employee Salary Data Analysis Using Excel | D12: 11_Salary | E12: 300 | F12: 7 | G12: Ready
A13: 12 | B13: Fartun Ali Maxamuud | C13: Fuel Consumption and Vehicle Analysis Using Excel | D13: 12_Fuel | E13: 300 | F13: 7 | G13: Ready
A14: 13 | B14: Faysal Mohamed Dahir | C14: Customer Demographic Data Analysis | D14: 13_Demographic | E14: 300 | F14: 7 | G14: Ready
A15: 14 | B15: Hawo Abdi Maxamed | C15: Weather and Temperature Data Analysis | D15: 14_Weather | E15: 300 | F15: 7 | G15: Ready
A16: 15 | B16: Hudeifa Mohamud Ahmed | C16: Monthly Expense and Budget Analysis | D16: 15_Budget | E16: 300 | F16: 7 | G16: Ready
A17: 16 | B17: Ibrahim Abdullahi Farhan | C17: Public Transportation Performance Analysis | D17: 16_Transport | E17: 300 | F17: 7 | G17: Ready
A18: 17 | B18: Miski Mohamed Abdullahi | C18: Hotel Booking and Customer Analysis | D18: 17_Hotel | E18: 300 | F18: 7 | G18: Ready
... A25: 24 | B25: Sucdi Yasin Husein | C25: Job Recruitment and Applicant Data Analysis | D25: 24_Recruitment | E25: 300 | F25: 7 | G25: Ready

Sheet Dashboard
B8: STUDENT ENROLLMENT DASHBOARD
B12: =COUNTA(#REF!) -> 1 | E12: =COUNTIF(#REF!,"Active") -> #REF! | I12: =COUNTIF(#REF!,"Graduated") -> #REF! | L12: =COUNTIF(#REF!,"Withdrawn") -> #REF!
B14: Total Students | E14: Active Students | I14: Graduated Students | L14: Withdrawn Students
B17: =SUM(#REF!) -> #REF! | I17: =AVERAGE(#REF!) -> #REF!
B20: Total Tuition Fee | I20: Average Tuition Fee

Sheet PivotGender
A3: Row Labels | B3: Count of Student_ID
A4: Female | B4: 148
A5: Male | B5: 136
A6: non_gender | B6: 16
A7: Grand Total | B7: 300

Sheet PivotProgram
A3: Row Labels | B3: Count of Student_ID
A4: Business Administration | B4: 47
A5: Computer Science | B5: 74
A6: Data Science | B6: 65
A7: Economics | B7: 25
A8: Engineering | B8: 37
A9: non_program | B9: 17
A10: Public Health | B10: 35
A11: Grand Total | B11: 300

Sheet PivotEnrollment_status
A3: Row Labels | B3: Count of Student_ID
A4: Active | B4: 175
A5: Deferred | B5: 27
A6: Graduated | B6: 64
A7: non_status | B7: 18
A8: Withdrawn | B8: 16
A9: Grand Total | B9: 300

Sheet PivotTuitionByProgram
A3: Row Labels | B3: Sum of Tuition_Fee
A4: Business Administration | B4: 36617.5
A5: Computer Science | B5: 68526.92
A6: Data Science | B6: 65662.73
A7: Economics | B7: 19402.25
A8: Engineering | B8: 42936.93
A9: non_program | B9: 17318.41
A10: Public Health | B10: 30457.95
A11: Grand Total | B11: 280922.69

Sheet PivotStady_mode
A3: Row Labels | B3: Count of Student_ID
A4: Full-Time | B4: 162
A5: non_stady_mode | B5: 19
A6: Online | B6: 60
A7: Part-Time | B7: 59
A8: Grand Total | B8: 300

Sheet PivotEnrollment_date
A3: Row Labels | B3: Count of Student_ID
A4: #VALUE! | B4: 18
A5: 1 | B5: 26
A6: 11 | B6: 23
A7: 12 | B7: 34
A8: 2 | B8: 20
A9: 3 | B9: 6
A10: 5 | B10: 10
A11: 6 | B11: 55
A12: 7 | B12: 78
A13: 8 | B13: 30
A14: Grand Total | B14: 300

Sheet PivotErollment_status
A3: Row Labels | B3: Count of Tuition_Fee
A4: Active | B4: 175
A5: Deferred | B5: 27
A6: Graduated | B6: 64
A7: non_status | B7: 18
A8: Withdrawn | B8: 16
A9: Grand Total | B9: 300

Sheet Sheet22
A3: Row Labels | B3: Sum of Tuition_Fee
A4: 45658 | B4: 772.18
A5: 45662 | B5: 1018
A6: 45663 | B6: 2298.6
A7: 45667 | B7: 1165.03
A8: 45668 | B8: 0
A9: 45669 | B9: 922.81
A10: 45672 | B10: 1087.06
A11: 45673 | B11: 984.71
A12: 45675 | B12: 1817.78
A13: 45678 | B13: 1022.73
A14: 45679 | B14: 858.41
A15: 45682 | B15: 1014.93
... A220: 46221 | B220: 1140.65
A221: Grand Total | B221: 262962.74

Sheet PivotTuitionByStudy_mode
A3: Row Labels | B3: Average of Tuition_Fee
A4: Active | B4: 973.18382
A5: Deferred | B5: 1057.798
A6: Graduated | B6: 1022.0213
A7: non_status | B7: 1003.02
A8: Withdrawn | B8: 1037.6264
A9: Grand Total | B9: 996.17975

Sheet Sheet29
A3: Row Labels | B3: Count of Tuition_Fee
A4: 1 | B4: 26
A5: 11 | B5: 23
A6: 12 | B6: 34
A7: 2 | B7: 20
A8: 3 | B8: 6
A9: 5 | B9: 10
A10: 6 | B10: 55
A11: 7 | B11: 78
A12: 8 | B12: 30
A13: Grand Total | B13: 282

Sheet DASHBOARD2
D6: DASHBOARD ENROLLMENT
D10: =GETPIVOTDATA("Student_ID",PivotGender!$A$3) -> 300 | G10: =GETPIVOTDATA("Tuition_Fee",PivotErollment_status!$A$3,"Enrollment_Status","Active") -> 175 | J10: =GETPIVOTDATA("Tuition_Fee",PivotErollment_status!$A$3,"Enrollment_Status","Graduated") -> 64 | M10: =GETPIVOTDATA("Tuition_Fee",PivotTuitionByStudy_mode!$A$3) -> 996.17975 | P10: =GETPIVOTDATA("Tuition_Fee",Avaregetuition!$A$3) -> 996.17975
D13: TOTAL STUDENT | G13: ACTIVE | J13: GRADUATED | M13: TOTAL TUITION | P13: AVG TUITION

Sheet Sheet31
A3: Row Labels | B3: Count of Tuition_Fee
A4: Full-Time | B4: 162
A5: non_stady_mode | B5: 19
A6: Online | B6: 60
A7: Part-Time | B7: 59
A8: Grand Total | B8: 300

Sheet Study_mode
A3: Row Labels | B3: Count of Student_ID
A4: Full-Time | B4: 162
A5: non_stady_mode | B5: 19
A6: Online | B6: 60
A7: Part-Time | B7: 59
A8: Grand Total | B8: 300

Sheet Avaregetuition
A3: Average of Tuition_Fee
A4: 996.17975

Sheet Data_clean
A1: Student_ID | B1: Gender | C1: Program | D1: Enrollment_Date | E1: Study_Mode | F1: Tuition_Fee | G1: Enrollment_Status | H1: Year | I1: Monthly | J1: Clean_Enrollment_Date
A2: ENR0001 | B2: Male | C2: Computer Science | D2: 45994 | E2: Full-Time | F2: 927.99 | G2: non_status | H2: =YEAR(Table1[[#This Row],[Enrollment_Date]]) -> 2025 | I2: =MONTH(Table1[[#This Row],[Enrollment_Date]]) -> 12 | J2: =IF(ISNUMBER(D2),D2,"") -> 45994
A3: ENR0002 | B3: Female | C3: Computer Science | D3: 45995 | E3: Online | F3: 929.8 | G3: Active | H3: =YEAR(Table1[[#This Row],[Enrollment_Date]]) -> 2025 | I3: =MONTH(Table1[[#This Row],[Enrollment_Date]]) -> 12 | J3: =IF(ISNUMBER(D3),D3,"") -> 45995
A4: ENR0003 | B4: Male | C4: Public Health | D4: 45996 | E4: Full-Time | F4: 1028.35 | G4: Active | H4: =YEAR(Table1[[#This Row],[Enrollment_Date]]) -> 2025 | I4: =MONTH(Table1[[#This Row],[Enrollment_Date]]) -> 12 | J4: =IF(ISNUMBER(D4),D4,"") -> 45996
A5: ENR0004 | B5: Male | C5: Data Science | D5: 45997 | E5: Part-Time | F5: 0 | G5: Active | H5: =YEAR(Table1[[#This Row],[Enrollment_Date]]) -> 2025 | I5: =MONTH(Table1[[#This Row],[Enrollment_Date]]) -> 12 | J5: =IF(ISNUMBER(D5),D5,"") -> 45997
A6: ENR0005 | B6: Female | C6: Computer Science | D6: 45998 | E6: Full-Time | F6: 1035.39 | G6: Active | H6: =YEAR(Table1[[#This Row],[Enrollment_Date]]) -> 2025 | I6: =MONTH(Table1[[#This Row],[Enrollment_Date]]) -> 12 | J6: =IF(ISNUMBER(D6),D6,"") -> 45998
A7: ENR0006 | B7: Female | C7: non_program | D7: 45999 | E7: Full-Time | F7: 1254.82 | G7: Withdrawn | H7: =YEAR(Table1[[#This Row],[Enrollment_Date]]) -> 2025 | I7: =MONTH(Table1[[#This Row],[Enrollment_Date]]) -> 12 | J7: =IF(ISNUMBER(D7),D7,"") -> 45999
A8: ENR0007 | B8: Male | C8: Public Health | D8: 46000 | E8: Full-Time | F8: 825.79 | G8: Graduated | H8: =YEAR(Table1[[#This Row],[Enrollment_Date]]) -> 2025 | I8: =MONTH(Table1[[#This Row],[Enrollment_Date]]) -> 12 | J8: =IF(ISNUMBER(D8),D8,"") -> 46000
A9: ENR0008 | B9: Male | C9: Computer Science | D9: 46001 | E9: Part-Time | F9: 1034.99 | G9: Deferred | H9: =YEAR(Table1[[#This Row],[Enrollment_Date]]) -> 2025 | I9: =MONTH(Table1[[#This Row],[Enrollment_Date]]) -> 12 | J9: =IF(ISNUMBER(D9),D9,"") -> 46001
A10: ENR0009 | B10: Female | C10: Computer Science | D10: 46002 | E10: Full-Time | F10: 1006.87 | G10: Active | H10: =YEAR(Table1[[#This Row],[Enrollment_Date]]) -> 2025 | I10: =MONTH(Table1[[#This Row],[Enrollment_Date]]) -> 12 | J10: =IF(ISNUMBER(D10),D10,"") -> 46002
A11: ENR0010 | B11: non_gender | C11: Computer Science | D11: 46003 | E11: Part-Time | F11: 896.69 | G11: Graduated | H11: =YEAR(Table1[[#This Row],[Enrollment_Date]]) -> 2025 | I11: =MONTH(Table1[[#This Row],[Enrollment_Date]]) -> 12 | J11: =IF(ISNUMBER(D11),D11,"") -> 46003
A12: ENR0011 | B12: Female | C12: Computer Science | D12: 46004 | E12: Part-Time | F12: 1046.24 | G12: Graduated | H12: =YEAR(Table1[[#This Row],[Enrollment_Date]]) -> 2025 | I12: =MONTH(Table1[[#This Row],[Enrollment_Date]]) -> 12 | J12: =IF(ISNUMBER(D12),D12,"") -> 46004
A13: ENR0012 | B13: Male | C13: Data Science | D13: 46005 | E13: non_stady_mode | F13: 0 | G13: Active | H13: =YEAR(Table1[[#This Row],[Enrollment_Date]]) -> 2025 | I13: =MONTH(Table1[[#This Row],[Enrollment_Date]]) -> 12 | J13: =IF(ISNUMBER(D13),D13,"") -> 46005
... A23: ENR0022 | B23: Female | C23: Public Health | D23: 46015 | E23: Full-Time | F23: 0 | G23: Withdrawn | H23: =YEAR(Table1[[#This Row],[Enrollment_Date]]) -> 2025 | I23: =MONTH(Table1[[#This Row],[Enrollment_Date]]) -> 12 | J23: =IF(ISNUMBER(D23),D23,"") -> 46015
A24: ENR0023 | B24: Female | C24: Data Science | D24: non_date | E24: Full-Time | F24: 1129.42 | G24: Graduated | H24: =YEAR(Table1[[#This Row],[Enrollment_Date]]) -> #VALUE! | I24: =MONTH(Table1[[#This Row],[Enrollment_Date]]) -> #VALUE! | J24: =IF(ISNUMBER(D24),D24,"")
A25: ENR0024 | B25: Female | C25: Data Science | D25: non_date | E25: Full-Time | F25: 1048 | G25: Active | H25: =YEAR(Table1[[#This Row],[Enrollment_Date]]) -> #VALUE! | I25: =MONTH(Table1[[#This Row],[Enrollment_Date]]) -> #VALUE! | J25: =IF(ISNUMBER(D25),D25,"")
A26: ENR0025 | B26: Female | C26: Data Science | D26: 45887 | E26: Full-Time | F26: 0 | G26: Active | H26: =YEAR(Table1[[#This Row],[Enrollment_Date]]) -> 2025 | I26: =MONTH(Table1[[#This Row],[Enrollment_Date]]) -> 8 | J26: =IF(ISNUMBER(D26),D26,"") -> 45887
A27: ENR0026 | B27: Male | C27: Computer Science | D27: 45888 | E27: non_stady_mode | F27: 1014.33 | G27: Graduated | H27: =YEAR(Table1[[#This Row],[Enrollment_Date]]) -> 2025 | I27: =MONTH(Table1[[#This Row],[Enrollment_Date]]) -> 8 | J27: =IF(ISNUMBER(D27),D27,"") -> 45888
A28: ENR0027 | B28: Male | C28: Public Health | D28: 45889 | E28: Full-Time | F28: 877.02 | G28: Active | H28: =YEAR(Table1[[#This Row],[Enrollment_Date]]) -> 2025 | I28: =MONTH(Table1[[#This Row],[Enrollment_Date]]) -> 8 | J28: =IF(ISNUMBER(D28),D28,"") -> 45889
A29: ENR0028 | B29: Female | C29: Data Science | D29: 45890 | E29: Full-Time | F29: 0 | G29: Active | H29: =YEAR(Table1[[#This Row],[Enrollment_Date]]) -> 2025 | I29: =MONTH(Table1[[#This Row],[Enrollment_Date]]) -> 8 | J29: =IF(ISNUMBER(D29),D29,"") -> 45890
A30: ENR0029 | B30: Male | C30: Public Health | D30: 45891 | E30: Full-Time | F30: 922.81 | G30: Active | H30: =YEAR(Table1[[#This Row],[Enrollment_Date]]) -> 2025 | I30: =MONTH(Table1[[#This Row],[Enrollment_Date]]) -> 8 | J30: =IF(ISNUMBER(D30),D30,"") -> 45891
A31: ENR0030 | B31: Male | C31: Data Science | D31: 45892 | E31: Full-Time | F31: 1155.26 | G31: Graduated | H31: =YEAR(Table1[[#This Row],[Enrollment_Date]]) -> 2025 | I31: =MONTH(Table1[[#This Row],[Enrollment_Date]]) -> 8 | J31: =IF(ISNUMBER(D31),D31,"") -> 45892
A32: ENR0031 | B32: Female | C32: Computer Science | D32: 45893 | E32: Full-Time | F32: 1064.99 | G32: Active | H32: =YEAR(Table1[[#This Row],[Enrollment_Date]]) -> 2025 | I32: =MONTH(Table1[[#This Row],[Enrollment_Date]]) -> 8 | J32: =IF(ISNUMBER(D32),D32,"") -> 45893
A33: ENR0032 | B33: Female | C33: Business Administration | D33: non_date | E33: non_stady_mode | F33: 808.66 | G33: Active | H33: =YEAR(Table1[[#This Row],[Enrollment_Date]]) -> #VALUE! | I33: =MONTH(Table1[[#This Row],[Enrollment_Date]]) -> #VALUE! | J33: =IF(ISNUMBER(D33),D33,"")
A34: ENR0033 | B34: Female | C34: Business Administration | D34: 46066 | E34: Part-Time | F34: 834.99 | G34: Active | H34: =YEAR(Table1[[#This Row],[Enrollment_Date]]) -> 2026 | I34: =MONTH(Table1[[#This Row],[Enrollment_Date]]) -> 2 | J34: =IF(ISNUMBER(D34),D34,"") -> 46066
A35: ENR0034 | B35: Male | C35: Public Health | D35: 46067 | E35: Full-Time | F35: 972.65 | G35: non_status | H35: =YEAR(Table1[[#This Row],[Enrollment_Date]]) -> 2026 | I35: =MONTH(Table1[[#This Row],[Enrollment_Date]]) -> 2 | J35: =IF(ISNUMBER(D35),D35,"") -> 46067
A36: ENR0035 | B36: Male | C36: Computer Science | D36: 46068 | E36: Online | F36: 886.2 | G36: non_status | H36: =YEAR(Table1[[#This Row],[Enrollment_Date]]) -> 2026 | I36: =MONTH(Table1[[#This Row],[Enrollment_Date]]) -> 2 | J36: =IF(ISNUMBER(D36),D36,"") -> 46068
A37: ENR0036 | B37: Female | C37: Business Administration | D37: 46069 | E37: non_stady_mode | F37: 866.74 | G37: non_status | H37: =YEAR(Table1[[#This Row],[Enrollment_Date]]) -> 2026 | I37: =MONTH(Table1[[#This Row],[Enrollment_Date]]) -> 2 | J37: =IF(ISNUMBER(D37),D37,"") -> 46069
A38: ENR0037 | B38: Male | C38: Data Science | D38: 46070 | E38: Full-Time | F38: 0 | G38: Active | H38: =YEAR(Table1[[#This Row],[Enrollment_Date]]) -> 2026 | I38: =MONTH(Table1[[#This Row],[Enrollment_Date]]) -> 2 | J38: =IF(ISNUMBER(D38),D38,"") -> 46070
A39: ENR0038 | B39: Female | C39: Business Administration | D39: 46071 | E39: Online | F39: 750.89 | G39: Active | H39: =YEAR(Table1[[#This Row],[Enrollment_Date]]) -> 2026 | I39: =MONTH(Table1[[#This Row],[Enrollment_Date]]) -> 2 | J39: =IF(ISNUMBER(D39),D39,"") -> 46071
A40: ENR0039 | B40: Male | C40: Business Administration | D40: 46072 | E40: Full-Time | F40: 736.59 | G40: Active | H40: =YEAR(Table1[[#This Row],[Enrollment_Date]]) -> 2026 | I40: =MONTH(Table1[[#This Row],[Enrollment_Date]]) -> 2 | J40: =IF(ISNUMBER(D40),D40,"") -> 46072
A41: ENR0040 | B41: Female | C41: Computer Science | D41: 46073 | E41: Full-Time | F41: 1071.49 | G41: Graduated | H41: =YEAR(Table1[[#This Row],[Enrollment_Date]]) -> 2026 | I41: =MONTH(Table1[[#This Row],[Enrollment_Date]]) -> 2 | J41: =IF(ISNUMBER(D41),D41,"") -> 46073
A42: ENR0041 | B42: Male | C42: Business Administration | D42: non_date | E42: Part-Time | F42: 838.79 | G42: Active | H42: =YEAR(Table1[[#This Row],[Enrollment_Date]]) -> #VALUE! | I42: =MONTH(Table1[[#This Row],[Enrollment_Date]]) -> #VALUE! | J42: =IF(ISNUMBER(D42),D42,"")
A43: ENR0042 | B43: non_gender | C43: Public Health | D43: 46213 | E43: Online | F43: 960.91 | G43: Active | H43: =YEAR(Table1[[#This Row],[Enrollment_Date]]) -> 2026 | I43: =MONTH(Table1[[#This Row],[Enrollment_Date]]) -> 7 | J43: =IF(ISNUMBER(D43),D43,"") -> 46213
A44: ENR0043 | B44: Male | C44: Engineering | D44: 46214 | E44: Part-Time | F44: 1354.04 | G44: Deferred | H44: =YEAR(Table1[[#This Row],[Enrollment_Date]]) -> 2026 | I44: =MONTH(Table1[[#This Row],[Enrollment_Date]]) -> 7 | J44: =IF(ISNUMBER(D44),D44,"") -> 46214
A45: ENR0044 | B45: Male | C45: Business Administration | D45: 46215 | E45: Full-Time | F45: 789.47 | G45: Deferred | H45: =YEAR(Table1[[#This Row],[Enrollment_Date]]) -> 2026 | I45: =MONTH(Table1[[#This Row],[Enrollment_Date]]) -> 7 | J45: =IF(ISNUMBER(D45),D45,"") -> 46215
A46: ENR0045 | B46: Female | C46: Engineering | D46: 46216 | E46: Online | F46: 1208.64 | G46: non_status | H46: =YEAR(Table1[[#This Row],[Enrollment_Date]]) -> 2026 | I46: =MONTH(Table1[[#This Row],[Enrollment_Date]]) -> 7 | J46: =IF(ISNUMBER(D46),D46,"") -> 46216
A47: ENR0046 | B47: Female | C47: Business Administration | D47: 46217 | E47: Full-Time | F47: 792.99 | G47: Active | H47: =YEAR(Table1[[#This Row],[Enrollment_Date]]) -> 2026 | I47: =MONTH(Table1[[#This Row],[Enrollment_Date]]) -> 7 | J47: =IF(ISNUMBER(D47),D47,"") -> 46217
A48: ENR0047 | B48: Female | C48: Data Science | D48: 46218 | E48: Online | F48: 1084.15 | G48: Graduated | H48: =YEAR(Table1[[#This Row],[Enrollment_Date]]) -> 2026 | I48: =MONTH(Table1[[#This Row],[Enrollment_Date]]) -> 7 | J48: =IF(ISNUMBER(D48),D48,"") -> 46218
A49: ENR0048 | B49: Female | C49: Engineering | D49: 46219 | E49: Full-Time | F49: 1305.94 | G49: Graduated | H49: =YEAR(Table1[[#This Row],[Enrollment_Date]]) -> 2026 | I49: =MONTH(Table1[[#This Row],[Enrollment_Date]]) -> 7 | J49: =IF(ISNUMBER(D49),D49,"") -> 46219
...

Sheet Enrollment_Row
A1: Student_ID | B1: Gender | C1: Program | D1: Enrollment_Date | E1: Study_Mode | F1: Tuition_Fee | G1: Enrollment_Status
A2: ENR0001 | B2: Male | C2: Computer Science | D2: 45994 | E2: Full-Time | F2: 927.99
A3: ENR0002 | B3: Female | C3: Computer Science | D3: 45772 | E3: Online | F3: 929.8 | G3: Active
A4: ENR0003 | B4: Male | C4: Public Health | D4: 46105 | E4: Full-Time | F4: 1028.35 | G4: Active
A5: ENR0004 | B5: Male | C5: Data Science | D5: 46121 | E5: Part-Time | G5: Active
A6: ENR0005 | B6: Female | C6: Computer Science | D6: 46010 | E6: full-time | F6: 1035.39 | G6: Active
A7: ENR0007 | B7: Female | D7: 45971 | E7: Full-Time | F7: 1254.82 | G7: Withdrawn
A8: ENR0008 | B8: Male | C8: Public Health | D8: 46040 | E8: Full-Time | F8: 825.79 | G8: Graduated
A9: ENR0009 | B9: Male | C9: Computer Science | D9: 45726 | E9: Part-Time | F9: 1034.99 | G9: Deferred
A10: ENR0010 | B10: Female | C10: Computer Science | D10: 45843 | E10: Full-Time | F10: 1006.87 | G10: Active | I10: =SUMIF(B2:B301,"Female",F2:F301) -> 137600.67
A11: ENR0011 | C11: Computer Science | D11: 45730 | E11: Part-Time | F11: 896.69 | G11: Graduated
A12: ENR0012 | B12: Female | C12: Computer Science | D12: 45692 | E12: Part-Time | F12: 1046.24 | G12: Graduated
A13: ENR0014 | B13: Male | C13: Data Science | D13: 46010 | F13: - | G13: Active
A14: ENR0015 | B14: Female | C14: Data Science | D14: 46221 | E14: Full-Time | F14: 1140.65 | G14: Active
A15: ENR0016 | B15: Male | C15: Computer Science | D15: 46011 | E15: Full-Time | F15: 890.93 | G15: Active
A16: ENR0017 | B16: Male | D16: 45748 | E16: Full-Time | F16: 1239.34 | G16: Withdrawn
A17: ENR0018 | B17: Female | D17: 46025 | E17: Online | F17: 1245.26 | G17: Deferred
A18: ENR0019 | B18: Male | C18: Data Science | D18: 46031 | E18: Full-Time | F18: 1175.69 | G18: Graduated
A19: ENR0020 | B19: Female | C19: Computer Science | D19: 46087 | E19: Online | F19: 905.83 | G19: Graduated
A20: ENR0021 | B20: Male | C20: Economics | D20: 46002 | E20: Part-Time | F20: 893.17 | G20: Active
A21: ENR0022 | C21: Data Science | D21: 45912 | E21: Full-Time | F21: 1065.37 | G21: Active
A22: ENR0023 | B22: Female | C22: Data Science | D22: 45801 | E22: Full-Time | F22: 1172 | G22: Deferred
A23: ENR0024 | B23: Female | C23: Public Health | D23: 45942 | E23: Full-Time | G23: Withdrawn
A24: ENR0025 | B24: Female | C24: Data Science | E24: Full-Time | F24: 1129.42 | G24: Graduated
A25: ENR0026 | B25: Female | C25: Data Science | D25: NULL | E25: Full-Time | F25: 1048 | G25: Active
A26: ENR0026 | B26: Female | C26: Data Science | D26: 45887 | E26: Full-Time | G26: Active
A27: ENR0027 | B27: Male | C27: Computer Science | D27: 45928 | F27: 1014.33 | G27: Graduated
A28: ENR0028 | B28: Male | C28: Public Health | D28: 45855 | E28: Full-Time | F28: 877.02 | G28: Active
A29: ENR0029 | B29: Female | C29: Data Science | D29: 45668 | E29: Full-Time | G29: Active
A30: ENR0030 | B30: Male | C30: Public Health | D30: 45669 | E30: Full-Time | F30: 922.81 | G30: Active
A31: ENR0031 | B31: Male | C31: Data Science | D31: 45706 | E31: Full-Time | F31: 1155.26 | G31: Graduated
A32: ENR0032 | B32: Female | C32: Computer Science | D32: 45968 | E32: Full-Time | F32: 1064.99 | G32: Active
A33: ENR0033 | B33: Female | C33: Business Administration | F33: 808.66 | G33: Active
A34: ENR0034 | B34: Female | C34: Business Administration | D34: 46066 | E34: Part-Time | F34: 834.99 | G34: Active
A35: ENR0035 | B35: Male | C35: Public Health | D35: 45804 | E35: Full-Time | F35: 972.65
A36: ENR0036 | B36: Male | C36: Computer Science | D36: 45892 | E36: Online | F36: 886.2
A37: ENR0037 | B37: Female | C37: Business Administration | D37: 45993 | F37: 866.74 | G37: N/A
A38: ENR0038 | B38: Male | C38: Data Science | D38: 45738 | E38: Full-Time | G38: Active
A39: ENR0039 | B39: Female | C39: Business Administration | D39: 45983 | E39: Online | F39: 750.89 | G39: Active
A40: ENR0040 | B40: Male | C40: Business Administration | D40: 45727 | E40: Full-Time | F40: 736.59 | G40: Active
...

Sheet Analaysi_data
A1: DATA BLANKES | G1: DATA COLOUM AND ROW
A3: 1 | B3: Student_ID | C3: =COUNTBLANK(Enrollment_Row!A2:A301) -> 15 | H3: DATA | I3: ROW | J3: BLANK
A4: 2 | B4: Gender | C4: =COUNTBLANK(Enrollment_Row!B2:B301) -> 15 | H4: Student_ID | I4: 301 | J4: 15 | K4: =I4-J4 -> 286
A5: 3 | B5: Program | C5: =COUNTBLANK(Enrollment_Row!C2:C301) -> 15 | H5: Gender | I5: 301 | J5: 15 | K5: =I5-J5 -> 286
A6: 4 | B6: Enrollment_Date | C6: =COUNTBLANK(Enrollment_Row!D2:D301) -> 16 | H6: Program | I6: 301 | J6: 15 | K6: =I6-J6 -> 286
A7: 5 | B7: Study_Mode | C7: =COUNTBLANK(Enrollment_Row!E2:E301) -> 15 | H7: Enrollment_Date | I7: 301 | J7: 16 | K7: =I7-J7 -> 285
A8: 6 | B8: Tuition_Fee | C8: =COUNTBLANK(Enrollment_Row!F2:F301) -> 15 | H8: Study_Mode | I8: 301 | J8: 15 | K8: =I8-J8 -> 286
A9: 7 | B9: Enrollment_Status | C9: =COUNTBLANK(Enrollment_Row!G2:G301) -> 16 | H9: Tuition_Fee | I9: 301 | J9: 15 | K9: =I9-J9 -> 286
A10: TOTAL BLANK | C10: =SUM(C3:C9) -> 107 | H10: Enrollment_Status | I10: 301 | J10: 16 | K10: =I10-J10 -> 285
H11: TOTAL DATA | K11: =SUM(K4:K10) -> 2000
A23: GENDER | G23: PROGRAM | L23: STUDY MODE | Q23: ENROLLMENT_STATUS
A24: 1 | B24: Male | C24: =COUNTIF(Enrollment_Row!B2:B301,"Female") -> 148 | G24: 1 | H24: BA | I24: =COUNTIF(Enrollment_Row!C2:C301,"BA") -> 1 | L24: 1 | M24: Full-Time | N24: =COUNTIF(Enrollment_Row!E2:E301,"Full-Time") -> 162 | Q24: 1 | R24: Active | S24: =COUNTIF(Enrollment_Row!G2:G301,"Active") -> 175
A25: 2 | B25: Female | C25: =COUNTIF(Enrollment_Row!B2:B301,"Male") -> 136 | G25: 2 | H25: Business Administration | I25: =COUNTIF(Enrollment_Row!C2:C301,"Business Administration") -> 46 | L25: 2 | M25: Part-Time | N25: =COUNTIF(Enrollment_Row!E2:E301,"Part-Time") -> 59 | Q25: 2 | R25: Deferred | S25: =COUNTIF(Enrollment_Row!G2:G301,"Deferred") -> 27
A26: 3 | B26: blank | C26: =COUNTIF(Enrollment_Row!B2:B301,"") -> 15 | G26: 3 | H26: Computer Science | I26: =COUNTIF(Enrollment_Row!C2:C301,"Computer Science") -> 73 | L26: 3 | M26: Online | N26: =COUNTIF(Enrollment_Row!E2:E301,"Online") -> 60 | Q26: 3 | R26: Graduated | S26: =COUNTIF(Enrollment_Row!G2:G301,"Graduated") -> 64
A27: 4 | B27: non value | C27: =COUNTIF(Enrollment_Row!B2:B301,"-") -> 1 | G27: 4 | H27: CS | I27: =COUNTIF(Enrollment_Row!C2:C301,"CS") -> 1 | L27: 4 | M27: N/A | N27: =COUNTIF(Enrollment_Row!E2:E301,"N/A") -> 2 | Q27: 4 | R27: N/A | S27: =COUNTIF(Enrollment_Row!G2:G301,"N/A") -> 2
A28: 5 | G28: 5 | H28: Data Science | I28: =COUNTIF(Enrollment_Row!C2:C301,"Data Science") -> 65 | L28: 5 | M28: NULL | N28: =COUNTIF(Enrollment_Row!E2:E301,"NULL") -> 2 | Q28: 5 | R28: Withdrawn | S28: =COUNTIF(Enrollment_Row!G2:G301,"Withdrawn") -> 16
A29: TOTAL | C29: =SUM(C24:C28) -> 300 | G29: 6 | H29: Economics | I29: =COUNTIF(Enrollment_Row!C2:C301,"Economics") -> 25 | L29: 6 | M29: Blank | N29: =COUNTIF(Enrollment_Row!E2:E301,"") -> 15 | Q29: 6 | R29: Blanks | S29: =COUNTIF(Enrollment_Row!G2:G301,"") -> 16
G30: 7 | H30: Engineering | I30: =COUNTIF(Enrollment_Row!C2:C301,"Engineering") -> 37 | L30: TOTAL | N30: =SUM(N24:N29) -> 300 | Q30: TOTAL | S30: =SUM(S24:S29) -> 300
G31: 8 | H31: Public Health | I31: =COUNTIF(Enrollment_Row!C2:C301,"Public Health") -> 35
G32: 9 | H32: NULL | I32: =COUNTIF(Enrollment_Row!C2:C301,"NULL") -> 1
G33: 10 | H33: Unknown | I33: =COUNTIF(Enrollment_Row!C2:C301,"Unknown") -> 1
G34: 11 | H34: blank | I34: =COUNTIF(Enrollment_Row!C2:C301,"") -> 15
G35: TOTAL | I35: =SUM(I24:I34) -> 300
A36: GENDER BY Tuition_Fee
A37: 1 | B37: Male | C37: =SUMIF(Enrollment_Row!B2:B301,"Male",Enrollment_Row!F2:F301) -> 127920.58
A38: 2 | B38: Female | C38: =SUMIF(Enrollment_Row!B2:B301,"Female",Enrollment_Row!F2:F301) -> 137600.67
A39: 3 | B39: blank | C39: =SUMIF(Enrollment_Row!B2:B301,"",Enrollment_Row!F2:F301) -> 14380
A40: 4 | B40: non value | C40: =SUMIF(Enrollment_Row!B2:B301,"-",Enrollment_Row!F2:F301) -> 1021.44
A41: TOTAL | C41: =SUM(C37:C40) -> 280922.69
A46: Program Tuition | G46: Erollment_status By Tuition | L46: Student_ID Dublicate | R46: Student_ID Apsent | W46: error text
B47: Program | C47: Tuition | H47: Erollment | I47: Tuition | R47: 1 | S47: 6 | X47: full-time | Y47: 1 | Z47: Full-Time
A48: 1 | B48: BA | C48: =SUMIF(Enrollment_Row!C2:C301,"BA",Enrollment_Row!F2:F301) -> 799.37 | H48: Active | I48: =SUMIF(Enrollment_Row!G2:G301,"Active",Enrollment_Row!F2:F301) -> 160575.33 | L48: 1 | M48: 26 | N48: 2 | R48: 2 | S48: 13 | X48: part-time | Y48: 1 | Z48: Part-Time
A49: 2 | B49: Business Administration | C49: =SUMIF(Enrollment_Row!C2:C301,"Business Administration",Enrollment_Row!F2:F301) -> 35818.13 | H49: Deferred | I49: =SUMIF(Enrollment_Row!G2:G301,"Deferred",Enrollment_Row!F2:F301) -> 26444.95 | L49: 2 | M49: 52 | N49: 2 | R49: 3 | S49: 55 | X49: FULL-TIME | Y49: 1 | Z49: Full-Time
A50: 3 | B50: Computer Science | C50: =SUMIF(Enrollment_Row!C2:C301,"Computer Science",Enrollment_Row!F2:F301) -> 67508.92 | H50: Graduated | I50: =SUMIF(Enrollment_Row!G2:G301,"Graduated",Enrollment_Row!F2:F301) -> 61321.28 | L50: 3 | M50: 61 | N50: 2 | R50: 4 | S50: 64 | X50: PART-TIME | Y50: 1 | Z50: Part-Time
A51: 4 | B51: CS | C51: =SUMIF(Enrollment_Row!C2:C301,"CS",Enrollment_Row!F2:F301) -> 1018 | H51: N/A | I51: =SUMIF(Enrollment_Row!G2:G301,"N/A",Enrollment_Row!F2:F301) -> 1767.91 | L51: 4 | M51: 71 | N51: 2 | R51: 5 | S51: 78 | X51: BA | Y51: 1 | Z51: Business Administration
A52: 5 | B52: Data Science | C52: =SUMIF(Enrollment_Row!C2:C301,"Data Science",Enrollment_Row!F2:F301) -> 65662.73 | H52: Withdrawn | I52: =SUMIF(Enrollment_Row!G2:G301,"Withdrawn",Enrollment_Row!F2:F301) -> 14526.77 | L52: 5 | M52: 199 | N52: 2 | R52: 6 | S52: 146 | X52: CS | Y52: 1 | Z52: Computer Science
A53: 6 | B53: Economics | C53: =SUMIF(Enrollment_Row!C2:C301,"Economics",Enrollment_Row!F2:F301) -> 19402.25 | H53: Blanks | I53: =SUMIF(Enrollment_Row!G2:G301,"",Enrollment_Row!F2:F301) -> 16286.45 | L53: 6 | M53: 256 | N53: 2 | R53: 7 | S53: 161 | X53: ACTIVE | Y53: 1 | Z53: Active
A54: 7 | B54: Engineering | C54: =SUMIF(Enrollment_Row!C2:C301,"Engineering",Enrollment_Row!F2:F301) -> 42936.93 | G54: TOTAL | I54: =SUM(I48:I53) -> 280922.69 | L54: 7 | M54: 279 | N54: 2 | R54: 8 | S54: 168 | X54: deferred | Y54: 1 | Z54: Deferred
A55: 8 | B55: Public Health | C55: =SUMIF(Enrollment_Row!C2:C301,"Public Health",Enrollment_Row!F2:F301) -> 30457.95 | R55: 9 | S55: 198 | X55: graduated | Y55: 1 | Z55: Graduated
A56: 9 | B56: NULL | C56: =SUMIF(Enrollment_Row!C2:C301,"NULL",Enrollment_Row!F2:F301) -> 936.29 | R56: 10 | S56: 236
...
